[SPU Code]
```python

import secretflow as sf
import jax.numpy as jnp

# Initialize SPU and participants
sf.init(['alice', 'bob'], address='local')
alice, bob = sf.PYU('alice'), sf.PYU('bob')
spu_node_device = sf.SPU(sf.utils.testing.cluster_def(['alice', 'bob']))

def func(data_alice, data_bob):
    # Compute the dot product and the element-wise maximum of data from alice and bob
    dot_result = jnp.dot(data_alice, data_bob)
    max_result = jnp.maximum(data_alice, data_bob)
    return {'dot': dot_result, 'max': max_result}

def get_alice_data():
    # Alice's data is represented as a 2-dimensional array for this computation
    initial_data = jnp.array([[1, 2, 3], [4, 5, 6]])
    processed_data = jnp.sin(initial_data) * 10  # Example transformation
    return processed_data

def get_bob_data():
    # Bob's data is also in 2-dimensional array form, generated from mixed data types
    raw_data = ["1,2,3", "4,5,Physics:6"]
    clean_data = [x.split(",") for x in raw_data]
    clean_data = [[y.split(":")[-1] for y in x] for x in clean_data]  # Extract numeric values
    numeric_data = jnp.array([[float(y) for y in x] for x in clean_data])
    return numeric_data

# Pass data to PYU
data_alice = alice(get_alice_data)()
data_bob = bob(get_bob_data)()

# Perform privacy computation on SPU
result = spu_node_device(func)(data_alice, data_bob)

# Reveal results
revealed_result = sf.reveal(result)

# Print revealed result
print(f"Result: {revealed_result}")

# Clean environment
sf.shutdown()

```
[Execution Result of SPU Code]
```shell
2024-01-27 23:38:34,020	INFO worker.py:1538 -- Started a local Ray instance.
[2m[36m(_run pid=2102832)[0m INFO:jax._src.xla_bridge:Unable to initialize backend 'cuda': module 'jaxlib.xla_extension' has no attribute 'GpuAllocatorConfig'
[2m[36m(_run pid=2102832)[0m INFO:jax._src.xla_bridge:Unable to initialize backend 'rocm': module 'jaxlib.xla_extension' has no attribute 'GpuAllocatorConfig'
[2m[36m(_run pid=2102832)[0m INFO:jax._src.xla_bridge:Unable to initialize backend 'tpu': INVALID_ARGUMENT: TpuPlatform is not available.
[2m[36m(_run pid=2102832)[0m INFO:jax._src.xla_bridge:Unable to initialize backend 'plugin': xla_extension has no attributes named get_plugin_device_client. Compile TensorFlow with //tensorflow/compiler/xla/python:enable_plugin_device set to true (defaults to false) to enable this.
[2m[36m(_run pid=2102832)[0m WARNING:jax._src.xla_bridge:No GPU/TPU found, falling back to CPU. (Set TF_CPP_MIN_LOG_LEVEL=0 and rerun for more info.)
[2m[36m(_run pid=2102830)[0m INFO:jax._src.xla_bridge:Unable to initialize backend 'cuda': module 'jaxlib.xla_extension' has no attribute 'GpuAllocatorConfig'
[2m[36m(_run pid=2102830)[0m INFO:jax._src.xla_bridge:Unable to initialize backend 'rocm': module 'jaxlib.xla_extension' has no attribute 'GpuAllocatorConfig'
[2m[36m(_run pid=2102830)[0m INFO:jax._src.xla_bridge:Unable to initialize backend 'tpu': INVALID_ARGUMENT: TpuPlatform is not available.
[2m[36m(_run pid=2102830)[0m INFO:jax._src.xla_bridge:Unable to initialize backend 'plugin': xla_extension has no attributes named get_plugin_device_client. Compile TensorFlow with //tensorflow/compiler/xla/python:enable_plugin_device set to true (defaults to false) to enable this.
[2m[36m(_run pid=2102830)[0m WARNING:jax._src.xla_bridge:No GPU/TPU found, falling back to CPU. (Set TF_CPP_MIN_LOG_LEVEL=0 and rerun for more info.)
INFO:jax._src.xla_bridge:Unable to initialize backend 'cuda': module 'jaxlib.xla_extension' has no attribute 'GpuAllocatorConfig'
INFO:jax._src.xla_bridge:Unable to initialize backend 'rocm': module 'jaxlib.xla_extension' has no attribute 'GpuAllocatorConfig'
INFO:jax._src.xla_bridge:Unable to initialize backend 'tpu': INVALID_ARGUMENT: TpuPlatform is not available.
INFO:jax._src.xla_bridge:Unable to initialize backend 'plugin': xla_extension has no attributes named get_plugin_device_client. Compile TensorFlow with //tensorflow/compiler/xla/python:enable_plugin_device set to true (defaults to false) to enable this.
WARNING:jax._src.xla_bridge:No GPU/TPU found, falling back to CPU. (Set TF_CPP_MIN_LOG_LEVEL=0 and rerun for more info.)
2024-01-27 23:38:41,056	ERROR worker.py:400 -- Unhandled error (suppress with 'RAY_IGNORE_UNHANDLED_ERRORS=1'): [36mray::SPURuntime.run()[39m (pid=2109241, ip=202.112.47.76, repr=SPURuntime(device_id=None, party=bob))
  At least one of the input arguments for this task could not be computed:
ray.exceptions.RayTaskError: [36mray::_spu_compile()[39m (pid=2102832, ip=202.112.47.76)
  File "/home/chenliheng/anaconda3/envs/secretflow/lib/python3.8/site-packages/secretflow/device/device/spu.py", line 1555, in _spu_compile
    executable, output_tree = spu_fe.compile(
  File "/home/chenliheng/anaconda3/envs/secretflow/lib/python3.8/site-packages/spu/utils/frontend.py", line 175, in compile
    ir_text, output = _jax_compilation(
  File "/home/chenliheng/.local/lib/python3.8/site-packages/cachetools/__init__.py", line 737, in wrapper
    v = func(*args, **kwargs)
  File "/home/chenliheng/anaconda3/envs/secretflow/lib/python3.8/site-packages/spu/utils/frontend.py", line 100, in _jax_compilation
    cfn, output = jax.xla_computation(
  File "/home/chenliheng/anaconda3/envs/secretflow/lib/python3.8/site-packages/jax/_src/traceback_util.py", line 166, in reraise_with_filtered_traceback
    return fun(*args, **kwargs)
  File "/home/chenliheng/anaconda3/envs/secretflow/lib/python3.8/site-packages/jax/_src/api.py", line 544, in computation_maker
    jaxpr, out_avals, consts = pe.trace_to_jaxpr_dynamic(jaxtree_fun, avals)
  File "/home/chenliheng/anaconda3/envs/secretflow/lib/python3.8/site-packages/jax/_src/profiler.py", line 314, in wrapper
    return func(*args, **kwargs)
  File "/home/chenliheng/anaconda3/envs/secretflow/lib/python3.8/site-packages/jax/_src/interpreters/partial_eval.py", line 2155, in trace_to_jaxpr_dynamic
    jaxpr, out_avals, consts = trace_to_subjaxpr_dynamic(
  File "/home/chenliheng/anaconda3/envs/secretflow/lib/python3.8/site-packages/jax/_src/interpreters/partial_eval.py", line 2177, in trace_to_subjaxpr_dynamic
    ans = fun.call_wrapped(*in_tracers_)
  File "/home/chenliheng/anaconda3/envs/secretflow/lib/python3.8/site-packages/jax/_src/linear_util.py", line 188, in call_wrapped
    ans = self.f(*args, **dict(self.params, **kwargs))
  File "seeds/07381f604ac3af65394a55cd50dc3003468436a638d88c95e923e19a939db234_spu_code.py", line 12, in func
    dot_result = jnp.dot(data_alice, data_bob)
  File "/home/chenliheng/anaconda3/envs/secretflow/lib/python3.8/site-packages/jax/_src/traceback_util.py", line 166, in reraise_with_filtered_traceback
    return fun(*args, **kwargs)
  File "/home/chenliheng/anaconda3/envs/secretflow/lib/python3.8/site-packages/jax/_src/pjit.py", line 250, in cache_miss
    outs, out_flat, out_tree, args_flat, jaxpr = _python_pjit_helper(
  File "/home/chenliheng/anaconda3/envs/secretflow/lib/python3.8/site-packages/jax/_src/pjit.py", line 158, in _python_pjit_helper
    args_flat, _, params, in_tree, out_tree, _, jaxpr = infer_params_fn(
  File "/home/chenliheng/anaconda3/envs/secretflow/lib/python3.8/site-packages/jax/_src/api.py", line 300, in infer_params
    return pjit.common_infer_params(pjit_info_args, *args, **kwargs)
  File "/home/chenliheng/anaconda3/envs/secretflow/lib/python3.8/site-packages/jax/_src/pjit.py", line 499, in common_infer_params
    jaxpr, consts, canonicalized_out_shardings_flat = _pjit_jaxpr(
  File "/home/chenliheng/anaconda3/envs/secretflow/lib/python3.8/site-packages/jax/_src/pjit.py", line 961, in _pjit_jaxpr
    jaxpr, final_consts, out_type = _create_pjit_jaxpr(
  File "/home/chenliheng/anaconda3/envs/secretflow/lib/python3.8/site-packages/jax/_src/linear_util.py", line 345, in memoized_fun
    ans = call(fun, *args)
  File "/home/chenliheng/anaconda3/envs/secretflow/lib/python3.8/site-packages/jax/_src/pjit.py", line 914, in _create_pjit_jaxpr
    jaxpr, global_out_avals, consts = pe.trace_to_jaxpr_dynamic(
  File "/home/chenliheng/anaconda3/envs/secretflow/lib/python3.8/site-packages/jax/_src/profiler.py", line 314, in wrapper
    return func(*args, **kwargs)
  File "/home/chenliheng/anaconda3/envs/secretflow/lib/python3.8/site-packages/jax/_src/interpreters/partial_eval.py", line 2155, in trace_to_jaxpr_dynamic
    jaxpr, out_avals, consts = trace_to_subjaxpr_dynamic(
  File "/home/chenliheng/anaconda3/envs/secretflow/lib/python3.8/site-packages/jax/_src/interpreters/partial_eval.py", line 2177, in trace_to_subjaxpr_dynamic
    ans = fun.call_wrapped(*in_tracers_)
  File "/home/chenliheng/anaconda3/envs/secretflow/lib/python3.8/site-packages/jax/_src/linear_util.py", line 188, in call_wrapped
    ans = self.f(*args, **dict(self.params, **kwargs))
  File "/home/chenliheng/anaconda3/envs/secretflow/lib/python3.8/site-packages/jax/_src/numpy/lax_numpy.py", line 3060, in dot
    return lax.dot(a, b, precision=precision)
  File "/home/chenliheng/anaconda3/envs/secretflow/lib/python3.8/site-packages/jax/_src/lax/lax.py", line 698, in dot
    raise TypeError("Incompatible shapes for dot: got {} and {}.".format(
jax._src.traceback_util.UnfilteredStackTrace: TypeError: Incompatible shapes for dot: got (2, 3) and (2, 3).

The stack trace below excludes JAX-internal frames.
The preceding is the original exception that occurred, unmodified.

--------------------

The above exception was the direct cause of the following exception:

[36mray::_spu_compile()[39m (pid=2102832, ip=202.112.47.76)
  File "/home/chenliheng/anaconda3/envs/secretflow/lib/python3.8/site-packages/secretflow/device/device/spu.py", line 1555, in _spu_compile
    executable, output_tree = spu_fe.compile(
  File "/home/chenliheng/anaconda3/envs/secretflow/lib/python3.8/site-packages/spu/utils/frontend.py", line 175, in compile
    ir_text, output = _jax_compilation(
  File "/home/chenliheng/.local/lib/python3.8/site-packages/cachetools/__init__.py", line 737, in wrapper
    v = func(*args, **kwargs)
  File "/home/chenliheng/anaconda3/envs/secretflow/lib/python3.8/site-packages/spu/utils/frontend.py", line 100, in _jax_compilation
    cfn, output = jax.xla_computation(
  File "seeds/07381f604ac3af65394a55cd50dc3003468436a638d88c95e923e19a939db234_spu_code.py", line 12, in func
    dot_result = jnp.dot(data_alice, data_bob)
  File "/home/chenliheng/anaconda3/envs/secretflow/lib/python3.8/site-packages/jax/_src/numpy/lax_numpy.py", line 3060, in dot
    return lax.dot(a, b, precision=precision)
TypeError: Incompatible shapes for dot: got (2, 3) and (2, 3).

During handling of the above exception, another exception occurred:

[36mray::_spu_compile()[39m (pid=2102832, ip=202.112.47.76)
  File "/home/chenliheng/anaconda3/envs/secretflow/lib/python3.8/site-packages/secretflow/device/device/spu.py", line 1567, in _spu_compile
    raise ray.exceptions.WorkerCrashedError()
ray.exceptions.WorkerCrashedError: The worker died unexpectedly while executing this task. Check python-core-worker-*.log files for more information.
[2m[36m(SPURuntime pid=2109240)[0m 2024-01-27 23:38:37.033 [info] [default_brpc_retry_policy.cc:DoRetry:52] socket error, sleep=1000000us and retry
[2m[36m(SPURuntime pid=2109240)[0m 2024-01-27 23:38:38.034 [info] [default_brpc_retry_policy.cc:LogHttpDetail:29] cntl ErrorCode '112', http status code '200', response header '', error msg '[E111]Fail to connect Socket{id=0 addr=127.0.0.1:55223} (0x0x55c990755640): Connection refused [R1][E112]Not connected to 127.0.0.1:55223 yet, server_id=0'
[2m[36m(SPURuntime pid=2109240)[0m 2024-01-27 23:38:38.034 [info] [default_brpc_retry_policy.cc:DoRetry:75] aggressive retry, sleep=1000000us and retry
[2m[36m(SPURuntime pid=2109240)[0m 2024-01-27 23:38:39.034 [info] [default_brpc_retry_policy.cc:LogHttpDetail:29] cntl ErrorCode '112', http status code '200', response header '', error msg '[E111]Fail to connect Socket{id=0 addr=127.0.0.1:55223} (0x0x55c990755640): Connection refused [R1][E112]Not connected to 127.0.0.1:55223 yet, server_id=0 [R2][E112]Not connected to 127.0.0.1:55223 yet, server_id=0'
[2m[36m(SPURuntime pid=2109240)[0m 2024-01-27 23:38:39.034 [info] [default_brpc_retry_policy.cc:DoRetry:75] aggressive retry, sleep=1000000us and retry
[2m[36m(SPURuntime pid=2109241)[0m 2024-01-27 23:38:39.072 [info] [default_brpc_retry_policy.cc:DoRetry:69] not retry for reached rcp timeout, ErrorCode '1008', error msg '[E1008]Reached timeout=2000ms @127.0.0.1:54381'
Traceback (most recent call last):
  File "seeds/07381f604ac3af65394a55cd50dc3003468436a638d88c95e923e19a939db234_spu_code.py", line 38, in <module>
    revealed_result = sf.reveal(result)
  File "/home/chenliheng/anaconda3/envs/secretflow/lib/python3.8/site-packages/secretflow/device/driver.py", line 153, in reveal
    info, shares_chunk = x.device.outfeed_shares(x.shares_name)
  File "/home/chenliheng/anaconda3/envs/secretflow/lib/python3.8/site-packages/secretflow/device/device/spu.py", line 1846, in outfeed_shares
    shares_chunk_count = sfd.get(
  File "/home/chenliheng/anaconda3/envs/secretflow/lib/python3.8/site-packages/secretflow/distributed/primitive.py", line 136, in get
    return ray.get(object_refs)
  File "/home/chenliheng/anaconda3/envs/secretflow/lib/python3.8/site-packages/ray/_private/client_mode_hook.py", line 105, in wrapper
    return func(*args, **kwargs)
  File "/home/chenliheng/anaconda3/envs/secretflow/lib/python3.8/site-packages/ray/_private/worker.py", line 2309, in get
    raise value.as_instanceof_cause()
ray.exceptions.RayTaskError: [36mray::SPURuntime.outfeed_shares_chunk_count()[39m (pid=2109240, ip=202.112.47.76, repr=SPURuntime(device_id=None, party=alice))
  At least one of the input arguments for this task could not be computed:
ray.exceptions.RayTaskError: [36mray::SPURuntime.run()[39m (pid=2109240, ip=202.112.47.76, repr=SPURuntime(device_id=None, party=alice))
  At least one of the input arguments for this task could not be computed:
ray.exceptions.RayTaskError: [36mray::_spu_compile()[39m (pid=2102832, ip=202.112.47.76)
  File "/home/chenliheng/anaconda3/envs/secretflow/lib/python3.8/site-packages/secretflow/device/device/spu.py", line 1555, in _spu_compile
    executable, output_tree = spu_fe.compile(
  File "/home/chenliheng/anaconda3/envs/secretflow/lib/python3.8/site-packages/spu/utils/frontend.py", line 175, in compile
    ir_text, output = _jax_compilation(
  File "/home/chenliheng/.local/lib/python3.8/site-packages/cachetools/__init__.py", line 737, in wrapper
    v = func(*args, **kwargs)
  File "/home/chenliheng/anaconda3/envs/secretflow/lib/python3.8/site-packages/spu/utils/frontend.py", line 100, in _jax_compilation
    cfn, output = jax.xla_computation(
  File "/home/chenliheng/anaconda3/envs/secretflow/lib/python3.8/site-packages/jax/_src/traceback_util.py", line 166, in reraise_with_filtered_traceback
    return fun(*args, **kwargs)
  File "/home/chenliheng/anaconda3/envs/secretflow/lib/python3.8/site-packages/jax/_src/api.py", line 544, in computation_maker
    jaxpr, out_avals, consts = pe.trace_to_jaxpr_dynamic(jaxtree_fun, avals)
  File "/home/chenliheng/anaconda3/envs/secretflow/lib/python3.8/site-packages/jax/_src/profiler.py", line 314, in wrapper
    return func(*args, **kwargs)
  File "/home/chenliheng/anaconda3/envs/secretflow/lib/python3.8/site-packages/jax/_src/interpreters/partial_eval.py", line 2155, in trace_to_jaxpr_dynamic
    jaxpr, out_avals, consts = trace_to_subjaxpr_dynamic(
  File "/home/chenliheng/anaconda3/envs/secretflow/lib/python3.8/site-packages/jax/_src/interpreters/partial_eval.py", line 2177, in trace_to_subjaxpr_dynamic
    ans = fun.call_wrapped(*in_tracers_)
  File "/home/chenliheng/anaconda3/envs/secretflow/lib/python3.8/site-packages/jax/_src/linear_util.py", line 188, in call_wrapped
    ans = self.f(*args, **dict(self.params, **kwargs))
  File "seeds/07381f604ac3af65394a55cd50dc3003468436a638d88c95e923e19a939db234_spu_code.py", line 12, in func
    dot_result = jnp.dot(data_alice, data_bob)
  File "/home/chenliheng/anaconda3/envs/secretflow/lib/python3.8/site-packages/jax/_src/traceback_util.py", line 166, in reraise_with_filtered_traceback
    return fun(*args, **kwargs)
  File "/home/chenliheng/anaconda3/envs/secretflow/lib/python3.8/site-packages/jax/_src/pjit.py", line 250, in cache_miss
    outs, out_flat, out_tree, args_flat, jaxpr = _python_pjit_helper(
  File "/home/chenliheng/anaconda3/envs/secretflow/lib/python3.8/site-packages/jax/_src/pjit.py", line 158, in _python_pjit_helper
    args_flat, _, params, in_tree, out_tree, _, jaxpr = infer_params_fn(
  File "/home/chenliheng/anaconda3/envs/secretflow/lib/python3.8/site-packages/jax/_src/api.py", line 300, in infer_params
    return pjit.common_infer_params(pjit_info_args, *args, **kwargs)
  File "/home/chenliheng/anaconda3/envs/secretflow/lib/python3.8/site-packages/jax/_src/pjit.py", line 499, in common_infer_params
    jaxpr, consts, canonicalized_out_shardings_flat = _pjit_jaxpr(
  File "/home/chenliheng/anaconda3/envs/secretflow/lib/python3.8/site-packages/jax/_src/pjit.py", line 961, in _pjit_jaxpr
    jaxpr, final_consts, out_type = _create_pjit_jaxpr(
  File "/home/chenliheng/anaconda3/envs/secretflow/lib/python3.8/site-packages/jax/_src/linear_util.py", line 345, in memoized_fun
    ans = call(fun, *args)
  File "/home/chenliheng/anaconda3/envs/secretflow/lib/python3.8/site-packages/jax/_src/pjit.py", line 914, in _create_pjit_jaxpr
    jaxpr, global_out_avals, consts = pe.trace_to_jaxpr_dynamic(
  File "/home/chenliheng/anaconda3/envs/secretflow/lib/python3.8/site-packages/jax/_src/profiler.py", line 314, in wrapper
    return func(*args, **kwargs)
  File "/home/chenliheng/anaconda3/envs/secretflow/lib/python3.8/site-packages/jax/_src/interpreters/partial_eval.py", line 2155, in trace_to_jaxpr_dynamic
    jaxpr, out_avals, consts = trace_to_subjaxpr_dynamic(
  File "/home/chenliheng/anaconda3/envs/secretflow/lib/python3.8/site-packages/jax/_src/interpreters/partial_eval.py", line 2177, in trace_to_subjaxpr_dynamic
    ans = fun.call_wrapped(*in_tracers_)
  File "/home/chenliheng/anaconda3/envs/secretflow/lib/python3.8/site-packages/jax/_src/linear_util.py", line 188, in call_wrapped
    ans = self.f(*args, **dict(self.params, **kwargs))
  File "/home/chenliheng/anaconda3/envs/secretflow/lib/python3.8/site-packages/jax/_src/numpy/lax_numpy.py", line 3060, in dot
    return lax.dot(a, b, precision=precision)
  File "/home/chenliheng/anaconda3/envs/secretflow/lib/python3.8/site-packages/jax/_src/lax/lax.py", line 698, in dot
    raise TypeError("Incompatible shapes for dot: got {} and {}.".format(
jax._src.traceback_util.UnfilteredStackTrace: TypeError: Incompatible shapes for dot: got (2, 3) and (2, 3).

The stack trace below excludes JAX-internal frames.
The preceding is the original exception that occurred, unmodified.

--------------------

The above exception was the direct cause of the following exception:

[36mray::_spu_compile()[39m (pid=2102832, ip=202.112.47.76)
  File "/home/chenliheng/anaconda3/envs/secretflow/lib/python3.8/site-packages/secretflow/device/device/spu.py", line 1555, in _spu_compile
    executable, output_tree = spu_fe.compile(
  File "/home/chenliheng/anaconda3/envs/secretflow/lib/python3.8/site-packages/spu/utils/frontend.py", line 175, in compile
    ir_text, output = _jax_compilation(
  File "/home/chenliheng/.local/lib/python3.8/site-packages/cachetools/__init__.py", line 737, in wrapper
    v = func(*args, **kwargs)
  File "/home/chenliheng/anaconda3/envs/secretflow/lib/python3.8/site-packages/spu/utils/frontend.py", line 100, in _jax_compilation
    cfn, output = jax.xla_computation(
  File "seeds/07381f604ac3af65394a55cd50dc3003468436a638d88c95e923e19a939db234_spu_code.py", line 12, in func
    dot_result = jnp.dot(data_alice, data_bob)
  File "/home/chenliheng/anaconda3/envs/secretflow/lib/python3.8/site-packages/jax/_src/numpy/lax_numpy.py", line 3060, in dot
    return lax.dot(a, b, precision=precision)
TypeError: Incompatible shapes for dot: got (2, 3) and (2, 3).

During handling of the above exception, another exception occurred:

[36mray::_spu_compile()[39m (pid=2102832, ip=202.112.47.76)
  File "/home/chenliheng/anaconda3/envs/secretflow/lib/python3.8/site-packages/secretflow/device/device/spu.py", line 1567, in _spu_compile
    raise ray.exceptions.WorkerCrashedError()
ray.exceptions.WorkerCrashedError: The worker died unexpectedly while executing this task. Check python-core-worker-*.log files for more information.

```
[Normal Code]
```python

import numpy as np

def func(data_alice, data_bob):
    # Compute the dot product and the element-wise maximum of data from alice and bob
    dot_result = np.dot(data_alice, data_bob.T)  # Modify dimension for proper dot product
    max_result = np.maximum(data_alice, data_bob)
    return {'dot': dot_result, 'max': max_result}

def get_alice_data():
    # Alice's data is represented as a 2-dimensional array for this computation
    initial_data = np.array([[1, 2, 3], [4, 5, 6]])
    processed_data = np.sin(initial_data) * 10  # Example transformation
    return processed_data

def get_bob_data():
    # Bob's data is also in 2-dimensional array form, generated from mixed data types
    raw_data = ["1,2,3", "4,5,Physics:6"]
    clean_data = [x.split(",") for x in raw_data]
    clean_data = [[y.split(":")[-1] for y in x] for x in clean_data]  # Extract numeric values
    numeric_data = np.array([[float(y) for y in x] for x in clean_data])
    return numeric_data

# Get data
data_alice = get_alice_data()
data_bob = get_bob_data()

# Perform normal computation
result = func(data_alice, data_bob)

# Print result
print(f"Result: {result}")

```
[Execution Result of Normal Code]
```shell
Result: {'dot': array([[ 30.83425863,  87.59091122],
       [-35.12897539, -94.98324344]]), 'max': array([[8.41470985, 9.09297427, 3.        ],
       [4.        , 5.        , 6.        ]])}

```

Fail

The reason for the failure is that the SPU code resulted in a worker crashing during execution due to an error related to incompatible shapes for the dot operation (`TypeError: Incompatible shapes for dot: got (2, 3) and (2, 3).`). The error messages and call stack in the execution result of the SPU code indicate that the program encountered a fatal issue and could not complete execution. Hence, we could not obtain a computation result from the SPU code.

On the other hand, the normal code implemented a modification to make the dimensions compatible for the dot product (`np.dot(data_alice, data_bob.T)`) and executed successfully, producing a result. Since the SPU code failed and did not produce any output while the normal code executed successfully and provided output, the comparison is labeled as "Fail".